{
  "action": {
    "error": {
      "variety": [
        "Malfunction"
      ], 
      "vector": [
        "Unknown"
      ]
    }
  }, 
  "actor": {
    "internal": {
      "motive": [
        "NA"
      ], 
      "variety": [
        "Unknown", 
        "Developer"
      ]
    }
  }, 
  "asset": {
    "assets": [
      {
        "variety": "S - Database"
      }
    ]
  }, 
  "attribute": {
    "confidentiality": {
      "data": [
        {
          "amount": 1, 
          "variety": "Personal"
        }
      ], 
      "data_disclosure": "Yes", 
      "data_total": 1, 
      "data_victim": [
        "Customer"
      ], 
      "state": [
        "Unknown"
      ]
    }
  }, 
  "discovery_method": "Int - reported by employee", 
  "impact": {
    "overall_rating": "Unknown"
  }, 
  "incident_id": "0C70CE66-FF2F-42FD-A595-D8C80C825D3F", 
  "plus": {
    "analysis_status": "Finalized", 
    "analyst": "Robert-Topper", 
    "attribute": {
      "confidentiality": {
        "credit_monitoring": "Y", 
        "data_misuse": "Y"
      }
    }, 
    "created": "2016-10-07T16:40:00Z", 
    "dbir_year": 2017, 
    "github": "7082", 
    "master_id": "0C70CE66-FF2F-42FD-A595-D8C80C825D3F", 
    "modified": "2016-10-07T16:40:00Z", 
    "sub_source": "VCDB", 
    "timeline": {
      "notification": {
        "month": 1, 
        "year": 2016
      }
    }
  }, 
  "reference": "http://www.theverge.com/2016/1/25/10827996/uber-driver-personal-data-mistake-glitch", 
  "schema_version": "1.3", 
  "security_incident": "Confirmed", 
  "source_id": "vcdb", 
  "summary": "PII mistakenly sent to other drivers as the result of a software glitch", 
  "timeline": {
    "incident": {
      "month": 1, 
      "year": 2016
    }
  }, 
  "victim": {
    "country": [
      "US"
    ], 
    "employee_count": "1001 to 10000", 
    "industry": "485310", 
    "region": [
      "019021"
    ], 
    "state": "CA", 
    "victim_id": "Uber"
  }
}